Workbook

Sheet Raw Data
A1: Autosampler Position | B1: Species ID | C1: Tree ID | D1: Lab No | E1: Lab ID | F1: FID File | G1: FID Date | H1: FID Time | I1: FID Channel CH4 | J1: Certified Value CO2 | K1: CH4 Area | L1: CH4 ppm | M1: CH4 Unit | N1: FID Channel CO2 | O1: Certified Value CO2 | P1: CO2 Area | Q1: CO2 ppm | R1: CO2 Unit | S1: ECD File | T1: ECD Date | U1: ECD Time | V1: ECD Channel O2 | W1: Certified Value O2 | X1: O2 Area | Y1: O2 ppm | Z1: ECD Channel N2O | AA1: Certified Value N2O | AB1: N2O Area | AC1: N2O ppm | AD1: N2O Unit
A2: 1 | B2: Lab Air Blank | C2: NA | D2: 1 | E2: Std1 | F2: F220930s01.CHR | G2: 44834 | H2: 0.32184028 | I2: CH4 | J2: 1.4 | K2: 0.2784 | L2: 1.5221 | M2: ppm | N2: CO2 | O2: 1.913 | P2: 95.474 | Q2: 143.2872 | R2: ppm | S2: E220930s01.CHR | T2: 44834 | U2: 0.32184028 | V2: O2 | W2: 1.163 | X2: 3236.0892 | Y2: 137445.32 | Z2: N2O | AA2: 2.213 | AB2: 51.8202 | AC2: 0.0136 | AD2: ppm
A3: 2 | B3: Lab Air Blank | C3: NA | D3: 2 | E3: Std2 | F3: F220930s02.CHR | G3: 44834 | H3: 0.32559028 | I3: CH4 | J3: 1.406 | K3: 0.2904 | L3: 1.574 | M3: ppm | N3: CO2 | O3: 1.92 | P3: 89.7547 | Q3: 122.1501 | R3: ppm | S3: E220930s02.CHR | T3: 44834 | U3: 0.32559028 | V3: O2 | W3: 1.166 | X3: 3113.7458 | Y3: 125334.54 | Z3: N2O | AA3: 2.216 | AB3: 49.3968 | AC3: 0.0037 | AD3: ppm
A4: 3 | B4: Lab Air Blank | C4: NA | D4: 3 | E4: Std3 | F4: F220930s03.CHR | G4: 44834 | H4: 0.32934028 | I4: CH4 | J4: 1.4 | K4: 0.3183 | L4: 1.6946 | M4: ppm | N4: CO2 | O4: 1.913 | P4: 102.7178 | Q4: 170.0584 | R4: ppm | S4: E220930s03.CHR | T4: 44834 | U4: 0.32934028 | V4: O2 | W4: 1.163 | X4: 3259.7308 | Y4: 139916.85 | Z4: N2O | AA4: 2.21 | AB4: 59.891 | AC4: 0.0467 | AD4: ppm
A5: 4 | B5: Lab Air Blank | C5: NA | D5: 4 | E5: Std4 | F5: F220930s04.CHR | G5: 44834 | H5: 0.33309028 | I5: CH4 | J5: 1.403 | K5: 0.3652 | L5: 1.8975 | M5: ppm | N5: CO2 | O5: 1.916 | P5: 109.1048 | Q5: 193.6631 | R5: ppm | S5: E220930s04.CHR | T5: 44834 | U5: 0.33309028 | V5: O2 | W5: 1.163 | X5: 3417.0822 | Y5: 159076.31 | Z5: N2O | AA5: 2.213 | AB5: 62.9926 | AC5: 0.0594 | AD5: ppm
A6: 5 | B6: Lab Air Blank | C6: NA | D6: 5 | E6: Std5 | F6: F220930s05.CHR | G6: 44834 | H6: 0.33685185 | I6: CH4 | J6: 1.403 | K6: 0.2958 | L6: 1.5973 | M6: ppm | N6: CO2 | O6: 1.913 | P6: 90.868 | Q6: 126.2646 | R6: ppm | S6: E220930s05.CHR | T6: 44834 | U6: 0.33685185 | V6: O2 | W6: 1.16 | X6: 3152.4221 | Y6: 129013.1 | Z6: N2O | AA6: 2.21 | AB6: 55.7088 | AC6: 0.0296 | AD6: ppm
A7: 6 | B7: Lab Air Blank | C7: NA | D7: 6 | E7: Std6 | F7: F220930s06.CHR | G7: 44834 | H7: 0.34061343 | I7: CH4 | J7: 1.41 | K7: 0.307 | L7: 1.6458 | M7: ppm | N7: CO2 | O7: 1.923 | P7: 88.9572 | Q7: 119.2027 | R7: ppm | S7: E220930s06.CHR | T7: 44834 | U7: 0.34061343 | V7: O2 | W7: 1.166 | X7: 3163.6668 | Y7: 130108.88 | Z7: N2O | AA7: 2.223 | AB7: 53.4684 | AC7: 0.0204 | AD7: ppm
A8: 7 | B8: Lab Air Blank | C8: NA | D8: 7 | E8: Std7 | F8: F220930s07.CHR | G8: 44834 | H8: 0.34436343 | I8: CH4 | J8: 1.413 | K8: 0.3333 | L8: 1.7595 | M8: ppm | N8: CO2 | O8: 1.926 | P8: 98.7931 | Q8: 155.5537 | R8: ppm | S8: E220930s07.CHR | T8: 44834 | U8: 0.34436343 | V8: O2 | W8: 1.17 | X8: 3300.4507 | Y8: 144501.4 | Z8: N2O | AA8: 2.226 | AB8: 56.1868 | AC8: 0.0315 | AD8: ppm
A9: 8 | B9: Lab Air Blank | C9: NA | D9: 8 | E9: Std8 | F9: F220930s08.CHR | G9: 44834 | H9: 0.34811343 | I9: CH4 | J9: 1.4 | K9: 0.3154 | L9: 1.6821 | M9: ppm | N9: CO2 | O9: 1.913 | P9: 94.3666 | Q9: 139.1945 | R9: ppm | S9: E220930s08.CHR | T9: 44834 | U9: 0.34811343 | V9: O2 | W9: 1.16 | X9: 3154.477 | Y9: 129213.35 | Z9: N2O | AA9: 2.21 | AB9: 53.4439 | AC9: 0.0203 | AD9: ppm
A10: 9 | B10: Lab Air Blank | C10: NA | D10: 9 | E10: Std9 | F10: F220930s09.CHR | G10: 44834 | H10: 0.35186343 | I10: CH4 | J10: 1.41 | K10: 0.2837 | L10: 1.545 | M10: ppm | N10: CO2 | O10: 1.926 | P10: 84.5659 | Q10: 102.9736 | R10: ppm | S10: E220930s09.CHR | T10: 44834 | U10: 0.35186343 | V10: O2 | W10: 1.166 | X10: 3065.4079 | Y10: 120923.37 | Z10: N2O | AA10: 2.226 | AB10: 50.3889 | AC10: 0.0078 | AD10: ppm
A11: 10 | B11: Lab Air Blank | C11: NA | D11: 10 | E11: Std10 | F11: F220930s10.CHR | G11: 44834 | H11: 0.35561343 | I11: CH4 | J11: 1.406 | K11: 0.3539 | L11: 1.8486 | M11: ppm | N11: CO2 | O11: 1.923 | P11: 109.2335 | Q11: 194.1388 | R11: ppm | S11: E220930s10.CHR | T11: 44834 | U11: 0.35561343 | V11: O2 | W11: 1.17 | X11: 3316.991 | Y11: 146366.28 | Z11: N2O | AA11: 2.22 | AB11: 59.3886 | AC11: 0.0447 | AD11: ppm
A12: 11 | B12: N2 | C12: NA | D12: 11 | E12: Std11 | F12: F220930s11.CHR | G12: 44834 | H12: 0.359375 | I12: CH4 | J12: 0 | K12: 0 | L12: 0 | M12: ppm | N12: CO2 | O12: 1.923 | P12: 42.255 | Q12: 0 | R12: ppm | S12: E220930s11.CHR | T12: 44834 | U12: 0.359375 | V12: O2 | W12: 1.166 | X12: 1197.8328 | Y12: 10817.772 | Z12: N2O | AA12: 2.22 | AB12: 18.776 | AC12: 0 | AD12: ppm
A13: 12 | B13: Lab Air Blank | C13: NA | D13: 12 | E13: Std12 | F13: F220930s12.CHR | G13: 44834 | H13: 0.36313657 | I13: CH4 | J13: 1.406 | K13: 0.2922 | L13: 1.5817 | M13: ppm | N13: CO2 | O13: 1.92 | P13: 82.3047 | Q13: 94.6168 | R13: ppm | S13: E220930s12.CHR | T13: 44834 | U13: 0.36313657 | V13: O2 | W13: 1.166 | X13: 2901.2608 | Y13: 107152.77 | Z13: N2O | AA13: 2.216 | AB13: 48.3396 | AC13: 0 | AD13: ppm
... A55: 54 | B55: Lab Air Blank | C55: NA | D55: 54 | E55: Std54 | F55: F220930s54.CHR | G55: 44834 | H55: 0.52103009 | I55: CH4 | J55: 1.41 | K55: 0.3578 | L55: 1.8655 | M55: ppm | N55: CO2 | O55: 1.946 | P55: 99.1488 | Q55: 156.8683 | R55: ppm | S55: E220930s54.CHR | T55: 44834 | U55: 0.52103009 | V55: O2 | W55: 1.166 | X55: 3073.4656 | Y55: 121658.69 | Z55: N2O | AA55: 2.256 | AB55: 62.1319 | AC55: 0.0559 | AD55: ppm
A56: 55 | B56: ACRU | C56: RM1 | D56: 55 | E56: =D56&"g" -> 55g | F56: F220930s55.CHR | G56: 44834 | H56: 0.52478009 | I56: CH4 | J56: 1.41 | K56: 6.239 | L56: 27.303 | M56: ppm | N56: CO2 | O56: 1.94 | P56: 17693.369 | Q56: 65180.644 | R56: ppm | S56: E220930s55.CHR | T56: 44834 | U56: 0.52478009 | V56: O2 | W56: 1.16 | X56: 2745.5214 | Y56: 95433.521 | Z56: N2O | AA56: 2.25 | AB56: 350.1718 | AC56: 1.2365 | AD56: ppm
A57: 56 | B57: BLANK | C57: BLANK | D57: 56 | E57: BLANK | F57: F220930s56.CHR | G57: 44834 | H57: 0.52853009 | I57: CH4 | J57: 0 | K57: 0 | L57: 0 | M57: ppm | N57: CO2 | O57: 1.956 | P57: 154.6102 | Q57: 361.8396 | R57: ppm | S57: E220930s56.CHR | T57: 44834 | U57: 0.52853009 | V57: O2 | W57: 1.166 | X57: 3198.6341 | Y57: 133529.72 | Z57: N2O | AA57: 2.263 | AB57: 66.5488 | AC57: 0.074 | AD57: ppm
A58: 57 | B58: ACRU | C58: RM10 | D58: 57 | E58: =D58&"g" -> 57g | F58: F220930s57.CHR | G58: 44834 | H58: 0.53228009 | I58: CH4 | J58: 1.42 | K58: 14.824 | L58: 64.435 | M58: ppm | N58: CO2 | O58: 1.966 | P58: 7544.7502 | Q58: 27673.923 | R58: ppm | S58: E220930s57.CHR | T58: 44834 | U58: 0.53228009 | V58: O2 | W58: 1.17 | X58: 3445.2342 | Y58: 163133.28 | Z58: N2O | AA58: 2.26 | AB58: 238.073 | AC58: 0.7771 | AD58: ppm
A59: 58 | B59: BLANK | C59: BLANK | D59: 58 | E59: BLANK | F59: F220930s58.CHR | G59: 44834 | H59: 0.53603009 | I59: CH4 | J59: 1.4 | K59: 0.2757 | L59: 1.5104 | M59: ppm | N59: CO2 | O59: 1.94 | P59: 146.9986 | Q59: 333.709 | R59: ppm | S59: E220930s58.CHR | T59: 44834 | U59: 0.53603009 | V59: O2 | W59: 1.16 | X59: 3168.6772 | Y59: 130597.14 | Z59: N2O | AA59: 2.246 | AB59: 66.7244 | AC59: 0.0747 | AD59: ppm
A60: 59 | B60: ACRU | C60: RM14 | D60: 59 | E60: =D60&"g" -> 59g | F60: F220930s59.CHR | G60: 44834 | H60: 0.53978009 | I60: CH4 | J60: 1.406 | K60: 0.5796 | L60: 2.8248 | M60: ppm | N60: CO2 | O60: 1.94 | P60: 812.0508 | Q60: 2791.5733 | R60: ppm | S60: E220930s59.CHR | T60: 44834 | U60: 0.53978009 | V60: O2 | W60: 1.16 | X60: 3542.5475 | Y60: 177484.93 | Z60: N2O | AA60: 2.243 | AB60: 112.7424 | AC60: 0.2633 | AD60: ppm
A61: 60 | B61: BLANK | C61: BLANK | D61: 60 | E61: BLANK | F61: F220930s60.CHR | G61: 44834 | H61: 0.54353009 | I61: CH4 | J61: 1.416 | K61: 0.2706 | L61: 1.4883 | M61: ppm | N61: CO2 | O61: 1.95 | P61: 85.9286 | Q61: 108.0098 | R61: ppm | S61: E220930s60.CHR | T61: 44834 | U61: 0.54353009 | V61: O2 | W61: 1.17 | X61: 3020.281 | Y61: 116996.09 | Z61: N2O | AA61: 2.26 | AB61: 52.3992 | AC61: 0.016 | AD61: ppm
A62: 61 | B62: ACRU | C62: RM2 | D62: 61 | E62: =D62&"g" -> 61g | F62: F220930s61.CHR | G62: 44834 | H62: 0.54726852 | I62: CH4 | J62: 1.406 | K62: 0.6522 | L62: 3.1388 | M62: ppm | N62: CO2 | O62: 1.94 | P62: 418.3445 | Q62: 1336.5347 | R62: ppm | S62: E220930s61.CHR | T62: 44834 | U62: 0.54726852 | V62: O2 | W62: 1.16 | X62: 3567.1041 | Y62: 181106.5 | Z62: N2O | AA62: 2.243 | AB62: 96.932 | AC62: 0.1985 | AD62: ppm
A63: 62 | B63: BLANK | C63: BLANK | D63: 62 | E63: BLANK | F63: F220930s62.CHR | G63: 44834 | H63: 0.55101852 | I63: CH4 | J63: 1.403 | K63: 0.3002 | L63: 1.6163 | M63: ppm | N63: CO2 | O63: 1.936 | P63: 93.5298 | Q63: 136.1019 | R63: ppm | S63: E220930s62.CHR | T63: 44834 | U63: 0.55101852 | V63: O2 | W63: 1.16 | X63: 2985.6592 | Y63: 114025.35 | Z63: N2O | AA63: 2.243 | AB63: 60.1067 | AC63: 0.0476 | AD63: ppm
A64: 63 | B64: ACRU | C64: RM3 | D64: 63 | E64: =D64&"g" -> 63g | F64: F220930s63.CHR | G64: 44834 | H64: 0.55475694 | I64: CH4 | J64: 1.406 | K64: 5.5582 | L64: 24.3584 | M64: ppm | N64: CO2 | O64: 1.943 | P64: 12837.626 | Q64: 47235.052 | R64: ppm | S64: E220930s63.CHR | T64: 44834 | U64: 0.55475694 | V64: O2 | W64: 1.156 | X64: 3030.5881 | Y64: 117880.49 | Z64: N2O | AA64: 2.24 | AB64: 290.5474 | AC64: 0.9921 | AD64: ppm
A65: 64 | B65: BLANK | C65: BLANK | D65: 64 | E65: BLANK | F65: F220930s64.CHR | G65: 44834 | H65: 0.55850694 | I65: CH4 | J65: 0 | K65: 0 | L65: 0 | M65: ppm | N65: CO2 | O65: 1.94 | P65: 89.08 | Q65: 119.6566 | R65: ppm | S65: E220930s64.CHR | T65: 44834 | U65: 0.55850694 | V65: O2 | W65: 1.16 | X65: 2872.0868 | Y65: 104890.72 | Z65: N2O | AA65: 2.25 | AB65: 51.8336 | AC65: 0.0137 | AD65: ppm
A66: 65 | B66: ACRU | C66: RM301A | D66: 65 | E66: =D66&"g" -> 65g | F66: F220930s65.CHR | G66: 44834 | H66: 0.56225694 | I66: CH4 | J66: 1.42 | K66: 69.3912 | L66: 300.4502 | M66: ppm | N66: CO2 | O66: 1.966 | P66: 4780.4642 | Q66: 17457.823 | R66: ppm | S66: E220930s65.CHR | T66: 44834 | U66: 0.56225694 | V66: O2 | W66: 1.166 | X66: 3423.3818 | Y66: 159918.85 | Z66: N2O | AA66: 2.26 | AB66: 195.1246 | AC66: 0.601 | AD66: ppm
A67: 66 | B67: BLANK | C67: BLANK | D67: 66 | E67: BLANK | F67: F220930s66.CHR | G67: 44834 | H67: 0.56599537 | I67: CH4 | J67: 1.403 | K67: 0.3121 | L67: 1.6678 | M67: ppm | N67: CO2 | O67: 1.943 | P67: 100.2808 | Q67: 161.0519 | R67: ppm | S67: E220930s66.CHR | T67: 44834 | U67: 0.56599537 | V67: O2 | W67: 1.16 | X67: 2928.1402 | Y67: 109329.14 | Z67: N2O | AA67: 2.256 | AB67: 57.9934 | AC67: 0.0389 | AD67: ppm
A68: 67 | B68: BLANK | C68: BLANK | D68: 67 | E68: BLANK | F68: F220930s67.CHR | G68: 44834 | H68: 0.56974537 | I68: CH4 | J68: 1.413 | K68: 0.367 | L68: 1.9053 | M68: ppm | N68: CO2 | O68: 1.95 | P68: 103.307 | Q68: 172.236 | R68: ppm | S68: E220930s67.CHR | T68: 44834 | U68: 0.56974537 | V68: O2 | W68: 1.166 | X68: 3120.945 | Y68: 125991.52 | Z68: N2O | AA68: 2.263 | AB68: 65.2266 | AC68: 0.0686 | AD68: ppm
A69: 68 | B69: BLANK | C69: BLANK | D69: 68 | E69: BLANK | F69: F220930s68.CHR | G69: 44834 | H69: 0.5734838 | I69: CH4 | J69: 1.406 | K69: 0.392 | L69: 2.0134 | M69: ppm | N69: CO2 | O69: 1.946 | P69: 130.0416 | Q69: 271.0403 | R69: ppm | S69: E220930s68.CHR | T69: 44834 | U69: 0.5734838 | V69: O2 | W69: 1.16 | X69: 3398.0848 | Y69: 156535.49 | Z69: N2O | AA69: 2.26 | AB69: 78.2518 | AC69: 0.122 | AD69: ppm
A70: 69 | B70: ACRU | C70: RM302 | D70: 69 | E70: =D70&"g" -> 69g | F70: F220930s69.CHR | G70: 44834 | H70: 0.5772338 | I70: CH4 | J70: 1.416 | K70: 111.1246 | L70: 480.9563 | M70: ppm | N70: CO2 | O70: 1.953 | P70: 15504.635 | Q70: 57091.638 | R70: ppm | S70: E220930s69.CHR | T70: 44834 | U70: 0.5772338 | V70: O2 | W70: 1.163 | X70: 2930.4281 | Y70: 109514.39 | Z70: N2O | AA70: 2.26 | AB70: 270.1277 | AC70: 0.9084 | AD70: ppm
A71: 70 | B71: BLANK | C71: BLANK | D71: 70 | E71: BLANK | F71: F220930s70.CHR | G71: 44834 | H71: 0.5809838 | I71: CH4 | J71: 1.396 | K71: 0.2794 | L71: 1.5264 | M71: ppm | N71: CO2 | O71: 1.94 | P71: 186.2842 | Q71: 478.8986 | R71: ppm | S71: E220930s70.CHR | T71: 44834 | U71: 0.5809838 | V71: O2 | W71: 1.156 | X71: 3165.513 | Y71: 130288.79 | Z71: N2O | AA71: 2.25 | AB71: 72.9088 | AC71: 0.1001 | AD71: ppm
A72: 71 | B72: ACRU | C72: RM303 | D72: 71 | E72: =D72&"g" -> 71g | F72: F220930s71.CHR | G72: 44834 | H72: 0.58472222 | I72: CH4 | J72: 1.41 | K72: 98.9529 | L72: 428.3111 | M72: ppm | N72: CO2 | O72: 1.953 | P72: 1924.3268 | Q72: 6902.2634 | R72: ppm | S72: E220930s71.CHR | T72: 44834 | U72: 0.58472222 | V72: O2 | W72: 1.163 | X72: 3514.092 | Y72: 173288.34 | Z72: N2O | AA72: 2.253 | AB72: 143.6808 | AC72: 0.3902 | AD72: ppm
A73: 72 | B73: BLANK | C73: BLANK | D73: 72 | E73: BLANK | F73: F220930s72.CHR | G73: 44834 | H73: 0.58847222 | I73: CH4 | J73: 1.416 | K73: 0.5121 | L73: 2.5329 | M73: ppm | N73: CO2 | O73: 1.953 | P73: 113.8435 | Q73: 211.1762 | R73: ppm | S73: E220930s72.CHR | T73: 44834 | U73: 0.58847222 | V73: O2 | W73: 1.166 | X73: 3152.307 | Y73: 129001.89 | Z73: N2O | AA73: 2.263 | AB73: 65.5125 | AC73: 0.0698 | AD73: ppm
A74: 73 | B74: Check Standard | C74: CHECK | D74: 73 | E74: ChkStd1 | F74: F220930s73.CHR | G74: 44834 | H74: 0.59222222 | I74: CH4 | J74: 1.403 | K74: 0.6713 | L74: 3.2214 | M74: ppm | N74: CO2 | O74: 1.943 | P74: 168.0021 | Q74: 411.3326 | R74: ppm | S74: E220930s73.CHR | T74: 44834 | U74: 0.59222222 | V74: O2 | W74: 1.16 | X74: 3826.2581 | Y74: 219326.21 | Z74: N2O | AA74: 2.253 | AB74: 113.9411 | AC74: 0.2683 | AD74: ppm
A75: 74 | B75: BLANK | C75: BLANK | D75: 74 | E75: BLANK | F75: F220930s74.CHR | G75: 44834 | H75: 0.59596065 | I75: CH4 | J75: 1.41 | K75: 0.371 | L75: 1.9226 | M75: ppm | N75: CO2 | O75: 1.943 | P75: 111.2203 | Q75: 201.4815 | R75: ppm | S75: E220930s74.CHR | T75: 44834 | U75: 0.59596065 | V75: O2 | W75: 1.16 | X75: 3188.0443 | Y75: 132484.43 | Z75: N2O | AA75: 2.253 | AB75: 69.864 | AC75: 0.0876 | AD75: ppm
A76: 75 | B76: ACRU | C76: RM4 | D76: 75 | E76: =D76&"g" -> 75g | F76: F220930s75.CHR | G76: 44834 | H76: 0.59971065 | I76: CH4 | J76: 1.416 | K76: 1.7448 | L76: 7.8646 | M76: ppm | N76: CO2 | O76: 1.953 | P76: 13961.122 | Q76: 51387.207 | R76: ppm | S76: E220930s75.CHR | T76: 44834 | U76: 0.59971065 | V76: O2 | W76: 1.166 | X76: 2925.6808 | Y76: 109130.01 | Z76: N2O | AA76: 2.256 | AB76: 737.1948 | AC76: 2.8229 | AD76: ppm
A77: 76 | B77: BLANK | C77: BLANK | D77: 76 | E77: BLANK | F77: F220930s76.CHR | G77: 44834 | H77: 0.60344907 | I77: CH4 | J77: 0 | K77: 0 | L77: 0 | M77: ppm | N77: CO2 | O77: 1.946 | P77: 111.8026 | Q77: 203.6335 | R77: ppm | S77: E220930s76.CHR | T77: 44834 | U77: 0.60344907 | V77: O2 | W77: 1.16 | X77: 3120.1516 | Y77: 125919.11 | Z77: N2O | AA77: 2.256 | AB77: 65.5618 | AC77: 0.07 | AD77: ppm
A78: 77 | B78: ACRU | C78: RM5 | D78: 77 | E78: =D78&"g" -> 77g | F78: F220930s77.CHR | G78: 44834 | H78: 0.60719907 | I78: CH4 | J78: 1.42 | K78: 1.5576 | L78: 7.0549 | M78: ppm | N78: CO2 | O78: 1.966 | P78: 2083.3947 | Q78: 7490.138 | R78: ppm | S78: E220930s77.CHR | T78: 44834 | U78: 0.60719907 | V78: O2 | W78: 1.17 | X78: 3592.9318 | Y78: 184915.54 | Z78: N2O | AA78: 2.266 | AB78: 145.6618 | AC78: 0.3983 | AD78: ppm
A79: 78 | B79: BLANK | C79: BLANK | D79: 78 | E79: BLANK | F79: F220930s78.CHR | G79: 44834 | H79: 0.61094907 | I79: CH4 | J79: 0 | K79: 0 | L79: 0 | M79: ppm | N79: CO2 | O79: 1.943 | P79: 41.4406 | Q79: 0 | R79: ppm | S79: E220930s78.CHR | T79: 44834 | U79: 0.61094907 | V79: O2 | W79: 1.156 | X79: 1063.3604 | Y79: 4970.1577 | Z79: N2O | AA79: 2.25 | AB79: 17.5692 | AC79: 0 | AD79: ppm
A80: 79 | B80: ACRU | C80: RM501 | D80: 79 | E80: =D80&"g" -> 79g | F80: F220930s79.CHR | G80: 44834 | H80: 0.6146875 | I80: CH4 | J80: 1.403 | K80: 0.4662 | L80: 2.3343 | M80: ppm | N80: CO2 | O80: 1.943 | P80: 250.2051 | Q80: 715.1341 | R80: ppm | S80: E220930s79.CHR | T80: 44834 | U80: 0.6146875 | V80: O2 | W80: 1.16 | X80: 3556.917 | Y80: 179604.12 | Z80: N2O | AA80: 2.253 | AB80: 93.9292 | AC80: 0.1862 | AD80: ppm
A81: 80 | B81: BLANK | C81: BLANK | D81: 80 | E81: BLANK | F81: F220930s80.CHR | G81: 44834 | H81: 0.6184375 | I81: CH4 | J81: 0 | K81: 0 | L81: 0 | M81: ppm | N81: CO2 | O81: 1.946 | P81: 43.0666 | Q81: 0 | R81: ppm | S81: E220930s80.CHR | T81: 44834 | U81: 0.6184375 | V81: O2 | W81: 1.163 | X81: 1215.7955 | Y81: 11605.813 | Z81: N2O | AA81: 2.263 | AB81: 18.6944 | AC81: 0 | AD81: ppm
...

Sheet Standard Concentrations
A1: Sample | B1: Stock [CO2] | C1: Stock [CH4] | D1: Stock [N2O] | E1: Stock [O2] | F1: mL Stock | G1: mL N2 | H1: [CO2] (ppm) | I1: [CH4] (ppm) | J1: [N2O] (ppm) | K1: [O2] (ppm)
A2: Lab Air Blank | B2: NA | C2: NA | D2: NA | E2: NA | F2: NA | G2: NA | H2: NA | I2: NA | J2: NA | K2: NA
A3: N2 | B3: 0 | C3: 0 | D3: 0 | E3: 0 | F3: 0 | G3: 18 | H3: 0 | I3: 0 | J3: 0 | K3: 0
A4: Outdoor Air 1 | B4: 415 | C4: 1.8 | D4: 0.325 | E4: 209500 | F4: 0 | G4: 18 | H4: 0 | I4: 0 | J4: 0 | K4: 0
A5: Outdoor Air 2 | B5: 415 | C5: 1.8 | D5: 0.325 | E5: 209500 | F5: 3 | G5: 15 | H5: 69.166667 | I5: 0.3 | J5: 0.0541667 | K5: 34916.667
A6: Outdoor Air 3 | B6: 415 | C6: 1.8 | D6: 0.325 | E6: 209500 | F6: 6 | G6: 12 | H6: 138.33333 | I6: 0.6 | J6: 0.108333 | K6: 69833.333
A7: Outdoor Air 4 | B7: 415 | C7: 1.8 | D7: 0.325 | E7: 209500 | F7: 9 | G7: 9 | H7: 207.5 | I7: 0.9 | J7: 0.1625 | K7: 104750
A8: Outdoor Air 5 | B8: 415 | C8: 1.8 | D8: 0.325 | E8: 209500 | F8: 12 | G8: 6 | H8: 276.66667 | I8: 1.2 | J8: 0.216667 | K8: 139666.67
A9: Outdoor Air 6 | B9: 415 | C9: 1.8 | D9: 0.325 | E9: 209500 | F9: 15 | G9: 3 | H9: 345.83333 | I9: 1.5 | J9: 0.270833 | K9: 174583.33
A10: Outdoor Air 7 | B10: 415 | C10: 1.8 | D10: 0.325 | E10: 209500 | F10: 18 | G10: 0 | H10: 415 | I10: 1.8 | J10: 0.325 | K10: 209500
A11: Oxygen Standard 1 | B11: 0 | C11: 0 | D11: 0 | E11: 1000000 | F11: 0 | G11: 18 | H11: 0 | I11: 0 | J11: 0 | K11: 0
A12: Oxygen Standard 2 | B12: 0 | C12: 0 | D12: 0 | E12: 1000000 | F12: 0.5 | G12: 17.5 | H12: 0 | I12: 0 | J12: 0 | K12: 27777.778
A13: Oxygen Standard 3 | B13: 0 | C13: 0 | D13: 0 | E13: 1000000 | F13: 1 | G13: 17 | H13: 0 | I13: 0 | J13: 0 | K13: 55555.556
A14: Oxygen Standard 4 | B14: 0 | C14: 0 | D14: 0 | E14: 1000000 | F14: 2 | G14: 16 | H14: 0 | I14: 0 | J14: 0 | K14: 111111.11
... A20: SB5 | B20: 10080 | C20: 5029 | D20: 5 | E20: 202000 | F20: 18 | G20: 0 | H20: 10080 | I20: 5029 | J20: 5 | K20: 202000
A21: SB6 | B21: 49990 | C21: 60340 | D21: 20 | F21: 18 | G21: 0 | H21: 49990 | I21: 60340 | J21: 20 | K21: 0

Sheet Run 1 Curves 1
A1: Autosampler Position | B1: Species ID | C1: Tree ID | D1: Lab No | E1: Lab ID | F1: FID File | G1: FID Date | H1: FID Time | I1: FID Channel CH4 | J1: Certified Value CO2 | K1: CH4 Area | L1: CH4 ppm | M1: CH4 Unit | N1: FID Channel CO2 | O1: Certified Value CO2 | P1: CO2 Area | Q1: CO2 ppm | R1: CO2 Unit | S1: ECD File | T1: ECD Date | U1: ECD Time | V1: ECD Channel O2 | W1: Certified Value O2 | X1: O2 Area | Y1: O2 ppm | Z1: ECD Channel N2O | AA1: Certified Value N2O | AB1: N2O Area | AC1: N2O ppm | AD1: N2O Unit | AE1: [CO2] (ppm) | AF1: [CH4] (ppm) | AG1: [N2O] (ppm) | AH1: [O2] (ppm)
A2: 1 | B2: Lab Air Blank | C2: NA | D2: 1 | E2: Std1 | F2: F220930s01.CHR | G2: 44834 | H2: 0.32184028 | I2: CH4 | J2: 1.4 | K2: 0.2784 | L2: 1.5221 | M2: ppm | N2: CO2 | O2: 1.913 | P2: 95.474 | Q2: 143.2872 | R2: ppm | S2: E220930s01.CHR | T2: 44834 | U2: 0.32184028 | V2: O2 | W2: 1.163 | X2: 3236.0892 | Y2: 137445.32 | Z2: N2O | AA2: 2.213 | AB2: 51.8202 | AC2: 0.0136 | AD2: ppm
A3: 2 | B3: Lab Air Blank | C3: NA | D3: 2 | E3: Std2 | F3: F220930s02.CHR | G3: 44834 | H3: 0.32559028 | I3: CH4 | J3: 1.406 | K3: 0.2904 | L3: 1.574 | M3: ppm | N3: CO2 | O3: 1.92 | P3: 89.7547 | Q3: 122.1501 | R3: ppm | S3: E220930s02.CHR | T3: 44834 | U3: 0.32559028 | V3: O2 | W3: 1.166 | X3: 3113.7458 | Y3: 125334.54 | Z3: N2O | AA3: 2.216 | AB3: 49.3968 | AC3: 0.0037 | AD3: ppm
A4: 3 | B4: Lab Air Blank | C4: NA | D4: 3 | E4: Std3 | F4: F220930s03.CHR | G4: 44834 | H4: 0.32934028 | I4: CH4 | J4: 1.4 | K4: 0.3183 | L4: 1.6946 | M4: ppm | N4: CO2 | O4: 1.913 | P4: 102.7178 | Q4: 170.0584 | R4: ppm | S4: E220930s03.CHR | T4: 44834 | U4: 0.32934028 | V4: O2 | W4: 1.163 | X4: 3259.7308 | Y4: 139916.85 | Z4: N2O | AA4: 2.21 | AB4: 59.891 | AC4: 0.0467 | AD4: ppm
A5: 4 | B5: Lab Air Blank | C5: NA | D5: 4 | E5: Std4 | F5: F220930s04.CHR | G5: 44834 | H5: 0.33309028 | I5: CH4 | J5: 1.403 | K5: 0.3652 | L5: 1.8975 | M5: ppm | N5: CO2 | O5: 1.916 | P5: 109.1048 | Q5: 193.6631 | R5: ppm | S5: E220930s04.CHR | T5: 44834 | U5: 0.33309028 | V5: O2 | W5: 1.163 | X5: 3417.0822 | Y5: 159076.31 | Z5: N2O | AA5: 2.213 | AB5: 62.9926 | AC5: 0.0594 | AD5: ppm
A6: 5 | B6: Lab Air Blank | C6: NA | D6: 5 | E6: Std5 | F6: F220930s05.CHR | G6: 44834 | H6: 0.33685185 | I6: CH4 | J6: 1.403 | K6: 0.2958 | L6: 1.5973 | M6: ppm | N6: CO2 | O6: 1.913 | P6: 90.868 | Q6: 126.2646 | R6: ppm | S6: E220930s05.CHR | T6: 44834 | U6: 0.33685185 | V6: O2 | W6: 1.16 | X6: 3152.4221 | Y6: 129013.1 | Z6: N2O | AA6: 2.21 | AB6: 55.7088 | AC6: 0.0296 | AD6: ppm
A7: 6 | B7: Lab Air Blank | C7: NA | D7: 6 | E7: Std6 | F7: F220930s06.CHR | G7: 44834 | H7: 0.34061343 | I7: CH4 | J7: 1.41 | K7: 0.307 | L7: 1.6458 | M7: ppm | N7: CO2 | O7: 1.923 | P7: 88.9572 | Q7: 119.2027 | R7: ppm | S7: E220930s06.CHR | T7: 44834 | U7: 0.34061343 | V7: O2 | W7: 1.166 | X7: 3163.6668 | Y7: 130108.88 | Z7: N2O | AA7: 2.223 | AB7: 53.4684 | AC7: 0.0204 | AD7: ppm
A8: 7 | B8: Lab Air Blank | C8: NA | D8: 7 | E8: Std7 | F8: F220930s07.CHR | G8: 44834 | H8: 0.34436343 | I8: CH4 | J8: 1.413 | K8: 0.3333 | L8: 1.7595 | M8: ppm | N8: CO2 | O8: 1.926 | P8: 98.7931 | Q8: 155.5537 | R8: ppm | S8: E220930s07.CHR | T8: 44834 | U8: 0.34436343 | V8: O2 | W8: 1.17 | X8: 3300.4507 | Y8: 144501.4 | Z8: N2O | AA8: 2.226 | AB8: 56.1868 | AC8: 0.0315 | AD8: ppm
A9: 8 | B9: Lab Air Blank | C9: NA | D9: 8 | E9: Std8 | F9: F220930s08.CHR | G9: 44834 | H9: 0.34811343 | I9: CH4 | J9: 1.4 | K9: 0.3154 | L9: 1.6821 | M9: ppm | N9: CO2 | O9: 1.913 | P9: 94.3666 | Q9: 139.1945 | R9: ppm | S9: E220930s08.CHR | T9: 44834 | U9: 0.34811343 | V9: O2 | W9: 1.16 | X9: 3154.477 | Y9: 129213.35 | Z9: N2O | AA9: 2.21 | AB9: 53.4439 | AC9: 0.0203 | AD9: ppm
A10: 9 | B10: Lab Air Blank | C10: NA | D10: 9 | E10: Std9 | F10: F220930s09.CHR | G10: 44834 | H10: 0.35186343 | I10: CH4 | J10: 1.41 | K10: 0.2837 | L10: 1.545 | M10: ppm | N10: CO2 | O10: 1.926 | P10: 84.5659 | Q10: 102.9736 | R10: ppm | S10: E220930s09.CHR | T10: 44834 | U10: 0.35186343 | V10: O2 | W10: 1.166 | X10: 3065.4079 | Y10: 120923.37 | Z10: N2O | AA10: 2.226 | AB10: 50.3889 | AC10: 0.0078 | AD10: ppm
A11: 10 | B11: Lab Air Blank | C11: NA | D11: 10 | E11: Std10 | F11: F220930s10.CHR | G11: 44834 | H11: 0.35561343 | I11: CH4 | J11: 1.406 | K11: 0.3539 | L11: 1.8486 | M11: ppm | N11: CO2 | O11: 1.923 | P11: 109.2335 | Q11: 194.1388 | R11: ppm | S11: E220930s10.CHR | T11: 44834 | U11: 0.35561343 | V11: O2 | W11: 1.17 | X11: 3316.991 | Y11: 146366.28 | Z11: N2O | AA11: 2.22 | AB11: 59.3886 | AC11: 0.0447 | AD11: ppm
A12: 12 | B12: Lab Air Blank | C12: NA | D12: 12 | E12: Std12 | F12: F220930s12.CHR | G12: 44834 | H12: 0.36313657 | I12: CH4 | J12: 1.406 | K12: 0.2922 | L12: 1.5817 | M12: ppm | N12: CO2 | O12: 1.92 | P12: 82.3047 | Q12: 94.6168 | R12: ppm | S12: E220930s12.CHR | T12: 44834 | U12: 0.36313657 | V12: O2 | W12: 1.166 | X12: 2901.2608 | Y12: 107152.77 | Z12: N2O | AA12: 2.216 | AB12: 48.3396 | AC12: 0 | AD12: ppm
A13: 14 | B13: Lab Air Blank | C13: NA | D13: 14 | E13: Std14 | F13: F220930s14.CHR | G13: 44834 | H13: 0.37064815 | I13: CH4 | J13: 1.4 | K13: 0.306 | L13: 1.6414 | M13: ppm | N13: CO2 | O13: 1.913 | P13: 94.8185 | Q13: 140.8646 | R13: ppm | S13: E220930s14.CHR | T13: 44834 | U13: 0.37064815 | V13: O2 | W13: 1.16 | X13: 3156.3932 | Y13: 129400.08 | Z13: N2O | AA13: 2.21 | AB13: 57.3174 | AC13: 0.0362 | AD13: ppm
... A36: 54 | B36: Lab Air Blank | C36: NA | D36: 54 | E36: Std54 | F36: F220930s54.CHR | G36: 44834 | H36: 0.52103009 | I36: CH4 | J36: 1.41 | K36: 0.3578 | L36: 1.8655 | M36: ppm | N36: CO2 | O36: 1.946 | P36: 99.1488 | Q36: 156.8683 | R36: ppm | S36: E220930s54.CHR | T36: 44834 | U36: 0.52103009 | V36: O2 | W36: 1.166 | X36: 3073.4656 | Y36: 121658.69 | Z36: N2O | AA36: 2.256 | AB36: 62.1319 | AC36: 0.0559 | AD36: ppm
A37: 11 | B37: N2 | C37: NA | D37: 11 | E37: Std11 | F37: F220930s11.CHR | G37: 44834 | H37: 0.359375 | I37: CH4 | J37: 0 | K37: 0 | L37: 0 | M37: ppm | N37: CO2 | O37: 1.923 | P37: 42.255 | Q37: 0 | R37: ppm | S37: E220930s11.CHR | T37: 44834 | U37: 0.359375 | V37: O2 | W37: 1.166 | X37: 1197.8328 | Y37: 10817.772 | Z37: N2O | AA37: 2.22 | AB37: 18.776 | AC37: 0 | AD37: ppm | AE37: 0 | AF37: 0 | AG37: 0 | AH37: 0
A38: 27 | B38: Outdoor Air 1 | C38: NA | D38: 27 | E38: Std27 | F38: F220930s27.CHR | G38: 44834 | H38: 0.41944444 | I38: CH4 | J38: 0 | K38: 0 | L38: 0 | M38: ppm | N38: CO2 | O38: 1.93 | P38: 12.7037 | Q38: 0 | R38: ppm | S38: E220930s27.CHR | T38: 44834 | U38: 0.41944444 | V38: O2 | W38: 1.156 | X38: 940.1134 | Y38: 0 | Z38: N2O | AA38: 2.24 | AB38: 6.5976 | AC38: 0 | AD38: ppm | AE38: 0 | AF38: 0 | AG38: 0 | AH38: 0
A39: 29 | B39: Outdoor Air 2 | C39: NA | D39: 29 | E39: Std29 | F39: F220930s29.CHR | G39: 44834 | H39: 0.42694444 | I39: CH4 | J39: 1.413 | K39: 0.1488 | L39: 0.9615 | M39: ppm | N39: CO2 | O39: 1.943 | P39: 39.931 | Q39: 0 | R39: ppm | S39: E220930s29.CHR | T39: 44834 | U39: 0.42694444 | V39: O2 | W39: 1.166 | X39: 1768.8222 | Y39: 37612.2 | Z39: N2O | AA39: 2.246 | AB39: 21.1202 | AC39: 0 | AD39: ppm | AE39: 69.166667 | AF39: 0.3 | AG39: 0.0541667 | AH39: 34916.667
A40: 31 | B40: Outdoor Air 3 | C40: NA | D40: 31 | E40: Std31 | F40: F220930s31.CHR | G40: 44834 | H40: 0.43444444 | I40: CH4 | J40: 1.406 | K40: 0.1988 | L40: 1.1778 | M40: ppm | N40: CO2 | O40: 1.94 | P40: 54.9004 | Q40: 0 | R40: ppm | S40: E220930s31.CHR | T40: 44834 | U40: 0.43444444 | V40: O2 | W40: 1.16 | X40: 2264.008 | Y40: 64358.638 | Z40: N2O | AA40: 2.246 | AB40: 33.4742 | AC40: 0 | AD40: ppm | AE40: 138.33333 | AF40: 0.6 | AG40: 0.108333 | AH40: 69833.333
A41: 33 | B41: Outdoor Air 4 | C41: NA | D41: 33 | E41: Std33 | F41: F220930s33.CHR | G41: 44834 | H41: 0.44193287 | I41: CH4 | J41: 1.406 | K41: 0.2935 | L41: 1.5874 | M41: ppm | N41: CO2 | O41: 1.936 | P41: 93.246 | Q41: 135.053 | R41: ppm | S41: E220930s33.CHR | T41: 44834 | U41: 0.44193287 | V41: O2 | W41: 1.156 | X41: 2677.8558 | Y41: 90646.03 | Z41: N2O | AA41: 2.246 | AB41: 48.0352 | AC41: 0 | AD41: ppm | AE41: 207.5 | AF41: 0.9 | AG41: 0.1625 | AH41: 104750
A42: 35 | B42: Outdoor Air 5 | C42: NA | D42: 35 | E42: Std35 | F42: F220930s35.CHR | G42: 44834 | H42: 0.4494213 | I42: CH4 | J42: 1.4 | K42: 0.4035 | L42: 2.0631 | M42: ppm | N42: CO2 | O42: 1.93 | P42: 101.3862 | Q42: 165.1372 | R42: ppm | S42: E220930s35.CHR | T42: 44834 | U42: 0.4494213 | V42: O2 | W42: 1.156 | X42: 2961.9964 | Y42: 112070.41 | Z42: N2O | AA42: 2.233 | AB42: 62.1276 | AC42: 0.0559 | AD42: ppm | AE42: 276.66667 | AF42: 1.2 | AG42: 0.216667 | AH42: 139666.67
A43: 37 | B43: Outdoor Air 6 | C43: NA | D43: 37 | E43: Std37 | F43: F220930s37.CHR | G43: 44834 | H43: 0.4569213 | I43: CH4 | J43: 1.403 | K43: 0.4554 | L43: 2.2876 | M43: ppm | N43: CO2 | O43: 1.936 | P43: 113.7486 | Q43: 210.8255 | R43: ppm | S43: E220930s37.CHR | T43: 44834 | U43: 0.4569213 | V43: O2 | W43: 1.156 | X43: 3321.0814 | Y43: 146841.16 | Z43: N2O | AA43: 2.246 | AB43: 72.8684 | AC43: 0.0999 | AD43: ppm | AE43: 345.83333 | AF43: 1.5 | AG43: 0.270833 | AH43: 174583.33
A44: 39 | B44: Outdoor Air 7 | C44: NA | D44: 39 | E44: Std39 | F44: F220930s39.CHR | G44: 44834 | H44: 0.46440972 | I44: CH4 | J44: 1.403 | K44: 0.5378 | L44: 2.644 | M44: ppm | N44: CO2 | O44: 1.936 | P44: 138.1706 | Q44: 301.083 | R44: ppm | S44: E220930s39.CHR | T44: 44834 | U44: 0.46440972 | V44: O2 | W44: 1.16 | X44: 3632.2025 | Y44: 190707.13 | Z44: N2O | AA44: 2.246 | AB44: 90.6894 | AC44: 0.173 | AD44: ppm | AE44: 415 | AF44: 1.8 | AG44: 0.325 | AH44: 209500
A45: 43 | B45: Oxygen Standard 1 | C45: NA | D45: 43 | E45: Std43 | F45: F220930s43.CHR | G45: 44834 | H45: 0.4794213 | I45: CH4 | J45: 0 | K45: 0 | L45: 0 | M45: ppm | N45: CO2 | O45: 1.936 | P45: 8.9723 | Q45: 0 | R45: ppm | S45: E220930s43.CHR | T45: 44834 | U45: 0.4794213 | V45: O2 | W45: 1.153 | X45: 781.4982 | Y45: 0 | Z45: N2O | AA45: 0 | AB45: 0 | AC45: 0 | AD45: ppm | AE45: 0 | AF45: 0 | AG45: 0 | AH45: 0
A46: 45 | B46: Oxygen Standard 2 | C46: NA | D46: 45 | E46: Std45 | F46: F220930s45.CHR | G46: 44834 | H46: 0.4869213 | I46: CH4 | J46: 0 | K46: 0 | L46: 0 | M46: ppm | N46: CO2 | O46: 1.936 | P46: 16.662 | Q46: 0 | R46: ppm | S46: E220930s45.CHR | T46: 44834 | U46: 0.4869213 | V46: O2 | W46: 1.156 | X46: 1655.343 | Y46: 31987.663 | Z46: N2O | AA46: 2.243 | AB46: 6.0114 | AC46: 0 | AD46: ppm | AE46: 0 | AF46: 0 | AG46: 0 | AH46: 27777.778
A47: 47 | B47: Oxygen Standard 3 | C47: NA | D47: 47 | E47: Std47 | F47: F220930s47.CHR | G47: 44834 | H47: 0.4944213 | I47: CH4 | J47: 0 | K47: 0 | L47: 0 | M47: ppm | N47: CO2 | O47: 1.936 | P47: 13.3037 | Q47: 0 | R47: ppm | S47: E220930s47.CHR | T47: 44834 | U47: 0.4944213 | V47: O2 | W47: 1.156 | X47: 2049.4194 | Y47: 52256.622 | Z47: N2O | AA47: 2.246 | AB47: 7.3668 | AC47: 0 | AD47: ppm | AE47: 0 | AF47: 0 | AG47: 0 | AH47: 55555.556
A48: 49 | B48: Oxygen Standard 4 | C48: NA | D48: 49 | E48: Std49 | F48: F220930s49.CHR | G48: 44834 | H48: 0.50190972 | I48: CH4 | J48: 0 | K48: 0 | L48: 0 | M48: ppm | N48: CO2 | O48: 1.943 | P48: 11.8392 | Q48: 0 | R48: ppm | S48: E220930s49.CHR | T48: 44834 | U48: 0.50190972 | V48: O2 | W48: 1.16 | X48: 2794.3532 | Y48: 98986.728 | Z48: N2O | AA48: 2.24 | AB48: 6.8631 | AC48: 0 | AD48: ppm | AE48: 0 | AF48: 0 | AG48: 0 | AH48: 111111.11
... A55: 23 | B55: SB6 | C55: NA | D55: 23 | E55: Std23 | F55: F220930s23.CHR | G55: 44834 | H55: 0.40443287 | I55: CH4 | J55: 1.383 | K55: 9889.3145 | L55: 42773.786 | M55: ppm | N55: CO2 | O55: 1.92 | P55: 11978.617 | Q55: 44060.372 | R55: ppm | S55: E220930s23.CHR | T55: 44834 | U55: 0.40443287 | V55: O2 | W55: 1.156 | X55: 1211.9922 | Y55: 11438.959 | Z55: N2O | AA55: 2.22 | AB55: 4841.1834 | AC55: 19.6447 | AD55: ppm | AE55: 49990 | AF55: 60340 | AG55: 20 | AH55: 0

Sheet Run 1 Curves 2
A1: Autosampler Position | B1: Species ID | C1: Tree ID | D1: Lab No | E1: Lab ID | F1: FID File | G1: FID Date | H1: FID Time | I1: FID Channel CH4 | J1: Certified Value CO2 | K1: CH4 Area | L1: CH4 ppm | M1: CH4 Unit | N1: FID Channel CO2 | O1: Certified Value CO2 | P1: CO2 Area | Q1: CO2 ppm | R1: CO2 Unit | S1: ECD File | T1: ECD Date | U1: ECD Time | V1: ECD Channel O2 | W1: Certified Value O2 | X1: O2 Area | Y1: O2 ppm | Z1: ECD Channel N2O | AA1: Certified Value N2O | AB1: N2O Area | AC1: N2O ppm | AD1: N2O Unit | AE1: [CO2] (ppm) | AF1: [CH4] (ppm) | AG1: [N2O] (ppm) | AH1: [O2] (ppm)
A2: 248 | B2: Lab Air Blank | C2: NA | D2: 248 | E2: Std 58 | F2: F220930s248.CHR | G2: 44835 | H2: 0.24912037 | I2: CH4 | J2: 1.41 | K2: 0.2816 | L2: 1.5359 | M2: ppm | N2: CO2 | O2: 1.936 | P2: 86.5304 | Q2: 110.2339 | R2: ppm | S2: E220930s248.CHR | T2: 44835 | U2: 0.24912037 | V2: O2 | W2: 1.166 | X2: 3036.54 | Y2: 118391.19 | Z2: N2O | AA2: 2.24 | AB2: 54.9326 | AC2: 0.0264 | AD2: ppm
A3: 250 | B3: Lab Air Blank | C3: NA | D3: 250 | E3: Std 60 | F3: F220930s250.CHR | G3: 44835 | H3: 0.25663194 | I3: CH4 | J3: 1.4 | K3: 0.3841 | L3: 1.9792 | M3: ppm | N3: CO2 | O3: 1.923 | P3: 102.1437 | Q3: 167.9367 | R3: ppm | S3: E220930s250.CHR | T3: 44835 | U3: 0.25663194 | V3: O2 | W3: 1.16 | X3: 3182.0819 | Y3: 131903.41 | Z3: N2O | AA3: 2.226 | AB3: 65.8062 | AC3: 0.071 | AD3: ppm
A4: 252 | B4: Lab Air Blank | C4: NA | D4: 252 | E4: Std 62 | F4: F220930s252.CHR | G4: 44835 | H4: 0.26413194 | I4: CH4 | J4: 1.403 | K4: 0.2952 | L4: 1.5947 | M4: ppm | N4: CO2 | O4: 1.923 | P4: 92.2128 | Q4: 131.2346 | R4: ppm | S4: E220930s252.CHR | T4: 44835 | U4: 0.26413194 | V4: O2 | W4: 1.16 | X4: 3020.3644 | Y4: 117003.24 | Z4: N2O | AA4: 2.226 | AB4: 58.5248 | AC4: 0.0411 | AD4: ppm
A5: 254 | B5: Lab Air Blank | C5: NA | D5: 254 | E5: Std 64 | F5: F220930s254.CHR | G5: 44835 | H5: 0.27164352 | I5: CH4 | J5: 1.413 | K5: 0.333 | L5: 1.7582 | M5: ppm | N5: CO2 | O5: 1.936 | P5: 94.8793 | Q5: 141.0893 | R5: ppm | S5: E220930s254.CHR | T5: 44835 | U5: 0.27164352 | V5: O2 | W5: 1.17 | X5: 3170.4208 | Y5: 130767.05 | Z5: N2O | AA5: 2.24 | AB5: 59.4368 | AC5: 0.0449 | AD5: ppm
A6: 256 | B6: Lab Air Blank | C6: NA | D6: 256 | E6: Std 66 | F6: F220930s256.CHR | G6: 44835 | H6: 0.27915509 | I6: CH4 | J6: 1.396 | K6: 0.2664 | L6: 1.4702 | M6: ppm | N6: CO2 | O6: 1.923 | P6: 84.9006 | Q6: 104.2106 | R6: ppm | S6: E220930s256.CHR | T6: 44835 | U6: 0.27915509 | V6: O2 | W6: 1.156 | X6: 2902.1556 | Y6: 107225.22 | Z6: N2O | AA6: 2.226 | AB6: 55.6386 | AC6: 0.0293 | AD6: ppm
A7: 258 | B7: Lab Air Blank | C7: NA | D7: 258 | E7: Std 68 | F7: F220930s258.CHR | G7: 44835 | H7: 0.28665509 | I7: CH4 | J7: 1.4 | K7: 0.4381 | L7: 2.2128 | M7: ppm | N7: CO2 | O7: 1.923 | P7: 89.2964 | Q7: 120.4563 | R7: ppm | S7: E220930s258.CHR | T7: 44835 | U7: 0.28665509 | V7: O2 | W7: 1.16 | X7: 2937.9926 | Y7: 110126.87 | Z7: N2O | AA7: 2.23 | AB7: 56.5497 | AC7: 0.033 | AD7: ppm
A8: 260 | B8: Lab Air Blank | C8: NA | D8: 260 | E8: Std 70 | F8: F220930s260.CHR | G8: 44835 | H8: 0.29416667 | I8: CH4 | J8: 1.4 | K8: 0.676 | L8: 3.2418 | M8: ppm | N8: CO2 | O8: 1.923 | P8: 87.3632 | Q8: 113.3117 | R8: ppm | S8: E220930s260.CHR | T8: 44835 | U8: 0.29416667 | V8: O2 | W8: 1.16 | X8: 2930.2114 | Y8: 109496.84 | Z8: N2O | AA8: 2.226 | AB8: 56.5456 | AC8: 0.033 | AD8: ppm
A9: 261 | B9: Lab Air Blank | C9: NA | D9: 261 | E9: Std 71 | F9: F220930s261.CHR | G9: 44835 | H9: 0.29791667 | I9: CH4 | J9: 1.4 | K9: 0.3614 | L9: 1.8811 | M9: ppm | N9: CO2 | O9: 1.926 | P9: 95.2716 | Q9: 142.5391 | R9: ppm | S9: E220930s261.CHR | T9: 44835 | U9: 0.29791667 | V9: O2 | W9: 1.16 | X9: 3071.5728 | Y9: 121485.96 | Z9: N2O | AA9: 2.226 | AB9: 62.4948 | AC9: 0.0574 | AD9: ppm
A10: 262 | B10: Lab Air Blank | C10: NA | D10: 262 | E10: Std 72 | F10: F220930s262.CHR | G10: 44835 | H10: 0.30166667 | I10: CH4 | J10: 1.406 | K10: 0.3361 | L10: 1.7716 | M10: ppm | N10: CO2 | O10: 1.923 | P10: 87.4685 | Q10: 113.7009 | R10: ppm | S10: E220930s262.CHR | T10: 44835 | U10: 0.30166667 | V10: O2 | W10: 1.16 | X10: 2994.0944 | Y10: 114749.14 | Z10: N2O | AA10: 2.23 | AB10: 55.8353 | AC10: 0.0301 | AD10: ppm
A11: 264 | B11: Lab Air Blank | C11: NA | D11: 264 | E11: Std 74 | F11: F220930s264.CHR | G11: 44835 | H11: 0.30916667 | I11: CH4 | J11: 1.41 | K11: 0.3352 | L11: 1.7677 | M11: ppm | N11: CO2 | O11: 1.936 | P11: 82.3652 | Q11: 94.8404 | R11: ppm | S11: E220930s264.CHR | T11: 44835 | U11: 0.30916667 | V11: O2 | W11: 1.166 | X11: 2964.8969 | Y11: 112305.26 | Z11: N2O | AA11: 2.24 | AB11: 50.2762 | AC11: 0.0073 | AD11: ppm
A12: 266 | B12: Lab Air Blank | C12: NA | D12: 266 | E12: Std 76 | F12: F220930s266.CHR | G12: 44835 | H12: 0.31667824 | I12: CH4 | J12: 1.4 | K12: 0.3556 | L12: 1.856 | M12: ppm | N12: CO2 | O12: 1.926 | P12: 99.6064 | Q12: 158.5595 | R12: ppm | S12: E220930s266.CHR | T12: 44835 | U12: 0.31667824 | V12: O2 | W12: 1.163 | X12: 3128.1214 | Y12: 126646.41 | Z12: N2O | AA12: 2.23 | AB12: 63.4863 | AC12: 0.0615 | AD12: ppm
A13: 268 | B13: Lab Air Blank | C13: NA | D13: 268 | E13: Std 78 | F13: F220930s268.CHR | G13: 44835 | H13: 0.32417824 | I13: CH4 | J13: 1.413 | K13: 0.3517 | L13: 1.8391 | M13: ppm | N13: CO2 | O13: 1.936 | P13: 101.2476 | Q13: 164.6249 | R13: ppm | S13: E220930s268.CHR | T13: 44835 | U13: 0.32417824 | V13: O2 | W13: 1.166 | X13: 3255.1024 | Y13: 139432.99 | Z13: N2O | AA13: 2.24 | AB13: 64.0502 | AC13: 0.0638 | AD13: ppm
... A26: 290 | B26: Lab Air Blank | C26: NA | D26: 290 | E26: Std 100 | F26: F220930s290.CHR | G26: 44835 | H26: 0.40680556 | I26: CH4 | J26: 1.413 | K26: 0.3554 | L26: 1.8551 | M26: ppm | N26: CO2 | O26: 1.936 | P26: 99.6422 | Q26: 158.6918 | R26: ppm | S26: E220930s290.CHR | T26: 44835 | U26: 0.40680556 | V26: O2 | W26: 1.17 | X26: 3258.3261 | Y26: 139770 | Z26: N2O | AA26: 2.24 | AB26: 62.8664 | AC26: 0.0589 | AD26: ppm
A27: 247 | B27: N2 | C27: NA | D27: 247 | E27: Std 57 | F27: F220930s247.CHR | G27: 44835 | H27: 0.2453588 | I27: CH4 | J27: 0 | K27: 0 | L27: 0 | M27: ppm | N27: CO2 | O27: 1.926 | P27: 50.4951 | Q27: 0 | R27: ppm | S27: E220930s247.CHR | T27: 44835 | U27: 0.2453588 | V27: O2 | W27: 1.156 | X27: 1221.3876 | Y27: 11851.144 | Z27: N2O | AA27: 2.233 | AB27: 20.7202 | AC27: 0 | AD27: ppm | AE27: 0 | AF27: 0 | AG27: 0 | AH27: 0
A28: 263 | B28: Outdoor Air 1 | C28: NA | D28: 263 | E28: Std 73 | F28: F220930s263.CHR | G28: 44835 | H28: 0.30541667 | I28: CH4 | J28: 0 | K28: 0 | L28: 0 | M28: ppm | N28: CO2 | O28: 1.923 | P28: 11.1068 | Q28: 0 | R28: ppm | S28: E220930s263.CHR | T28: 44835 | U28: 0.30541667 | V28: O2 | W28: 1.153 | X28: 840.5132 | Y28: 0 | Z28: N2O | AA28: 2.223 | AB28: 5.0726 | AC28: 0 | AD28: ppm | AE28: 0 | AF28: 0 | AG28: 0 | AH28: 0
A29: 265 | B29: Outdoor Air 2 | C29: NA | D29: 265 | E29: Std 75 | F29: F220930s265.CHR | G29: 44835 | H29: 0.31292824 | I29: CH4 | J29: 1.4 | K29: 0.1412 | L29: 0.9286 | M29: ppm | N29: CO2 | O29: 1.926 | P29: 32.3927 | Q29: 0 | R29: ppm | S29: E220930s265.CHR | T29: 44835 | U29: 0.31292824 | V29: O2 | W29: 1.16 | X29: 1716.9178 | Y29: 35018.169 | Z29: N2O | AA29: 2.233 | AB29: 19.4509 | AC29: 0 | AD29: ppm | AE29: 69.166667 | AF29: 0.3 | AG29: 0.0541667 | AH29: 34916.667
A30: 267 | B30: Outdoor Air 3 | C30: NA | D30: 267 | E30: Std 77 | F30: F220930s267.CHR | G30: 44835 | H30: 0.32042824 | I30: CH4 | J30: 1.396 | K30: 0.2264 | L30: 1.2971 | M30: ppm | N30: CO2 | O30: 1.92 | P30: 53.2743 | Q30: 0 | R30: ppm | S30: E220930s267.CHR | T30: 44835 | U30: 0.32042824 | V30: O2 | W30: 1.156 | X30: 2189.3794 | Y30: 60025.865 | Z30: N2O | AA30: 2.223 | AB30: 32.9252 | AC30: 0 | AD30: ppm | AE30: 138.33333 | AF30: 0.6 | AG30: 0.108333 | AH30: 69833.333
A31: 269 | B31: Outdoor Air 4 | C31: NA | D31: 269 | E31: Std 79 | F31: F220930s269.CHR | G31: 44835 | H31: 0.32792824 | I31: CH4 | J31: 1.41 | K31: 0.2696 | L31: 1.484 | M31: ppm | N31: CO2 | O31: 1.933 | P31: 74.6908 | Q31: 66.4777 | R31: ppm | S31: E220930s269.CHR | T31: 44835 | U31: 0.32792824 | V31: O2 | W31: 1.166 | X31: 2719.0419 | Y31: 93506.761 | Z31: N2O | AA31: 2.24 | AB31: 46.7632 | AC31: 0 | AD31: ppm | AE31: 207.5 | AF31: 0.9 | AG31: 0.1625 | AH31: 104750
A32: 271 | B32: Outdoor Air 5 | C32: NA | D32: 271 | E32: Std 81 | F32: F220930s271.CHR | G32: 44835 | H32: 0.33546296 | I32: CH4 | J32: 1.41 | K32: 0.4114 | L32: 2.0973 | M32: ppm | N32: CO2 | O32: 1.93 | P32: 101.0642 | Q32: 163.9471 | R32: ppm | S32: E220930s271.CHR | T32: 44835 | U32: 0.33546296 | V32: O2 | W32: 1.17 | X32: 3117.893 | Y32: 125713 | Z32: N2O | AA32: 2.23 | AB32: 66.3155 | AC32: 0.073 | AD32: ppm | AE32: 276.66667 | AF32: 1.2 | AG32: 0.216667 | AH32: 139666.67
A33: 273 | B33: Outdoor Air 6 | C33: NA | D33: 273 | E33: Std 83 | F33: F220930s273.CHR | G33: 44835 | H33: 0.34296296 | I33: CH4 | J33: 1.413 | K33: 0.398 | L33: 2.0394 | M33: ppm | N33: CO2 | O33: 1.936 | P33: 113.2686 | Q33: 209.0515 | R33: ppm | S33: E220930s273.CHR | T33: 44835 | U33: 0.34296296 | V33: O2 | W33: 1.17 | X33: 3400.2834 | Y33: 156829.54 | Z33: N2O | AA33: 2.24 | AB33: 78.8412 | AC33: 0.1244 | AD33: ppm | AE33: 345.83333 | AF33: 1.5 | AG33: 0.270833 | AH33: 174583.33
A34: 275 | B34: Outdoor Air 7 | C34: NA | D34: 275 | E34: Std 85 | F34: F220930s275.CHR | G34: 44835 | H34: 0.35047454 | I34: CH4 | J34: 1.403 | K34: 0.5032 | L34: 2.4944 | M34: ppm | N34: CO2 | O34: 1.926 | P34: 140.2195 | Q34: 308.6552 | R34: ppm | S34: E220930s275.CHR | T34: 44835 | U34: 0.35047454 | V34: O2 | W34: 1.163 | X34: 3609.48 | Y34: 187356.05 | Z34: N2O | AA34: 2.23 | AB34: 90.1022 | AC34: 0.1705 | AD34: ppm | AE34: 415 | AF34: 1.8 | AG34: 0.325 | AH34: 209500
A35: 279 | B35: Oxygen Standard 1 | C35: NA | D35: 279 | E35: Std 89 | F35: F220930s279.CHR | G35: 44835 | H35: 0.36549769 | I35: CH4 | J35: 0 | K35: 0 | L35: 0 | M35: ppm | N35: CO2 | O35: 1.923 | P35: 17.9212 | Q35: 0 | R35: ppm | S35: E220930s279.CHR | T35: 44835 | U35: 0.36549769 | V35: O2 | W35: 1.153 | X35: 836.047 | Y35: 0 | Z35: N2O | AA35: 2.236 | AB35: 6.3549 | AC35: 0 | AD35: ppm | AE35: 0 | AF35: 0 | AG35: 0 | AH35: 0
A36: 281 | B36: Oxygen Standard 2 | C36: NA | D36: 281 | E36: Std 91 | F36: F220930s281.CHR | G36: 44835 | H36: 0.37300926 | I36: CH4 | J36: 0 | K36: 0 | L36: 0 | M36: ppm | N36: CO2 | O36: 1.923 | P36: 20.567 | Q36: 0 | R36: ppm | S36: E220930s281.CHR | T36: 44835 | U36: 0.37300926 | V36: O2 | W36: 1.156 | X36: 1639.793 | Y36: 31236.651 | Z36: N2O | AA36: 2.23 | AB36: 6.9697 | AC36: 0 | AD36: ppm | AE36: 0 | AF36: 0 | AG36: 0 | AH36: 27777.778
A37: 283 | B37: Oxygen Standard 3 | C37: NA | D37: 283 | E37: Std 93 | F37: F220930s283.CHR | G37: 44835 | H37: 0.38052083 | I37: CH4 | J37: 0 | K37: 0 | L37: 0 | M37: ppm | N37: CO2 | O37: 1.923 | P37: 10.5108 | Q37: 0 | R37: ppm | S37: E220930s283.CHR | T37: 44835 | U37: 0.38052083 | V37: O2 | W37: 1.156 | X37: 2026.193 | Y37: 51009.01 | Z37: N2O | AA37: 2.23 | AB37: 6.2001 | AC37: 0 | AD37: ppm | AE37: 0 | AF37: 0 | AG37: 0 | AH37: 55555.556
A38: 285 | B38: Oxygen Standard 4 | C38: NA | D38: 285 | E38: Std 95 | F38: F220930s285.CHR | G38: 44835 | H38: 0.38803241 | I38: CH4 | J38: 0 | K38: 0 | L38: 0 | M38: ppm | N38: CO2 | O38: 1.926 | P38: 11.1026 | Q38: 0 | R38: ppm | S38: E220930s285.CHR | T38: 44835 | U38: 0.38803241 | V38: O2 | W38: 1.16 | X38: 2753.8782 | Y38: 96041.597 | Z38: N2O | AA38: 2.23 | AB38: 6.3876 | AC38: 0 | AD38: ppm | AE38: 0 | AF38: 0 | AG38: 0 | AH38: 111111.11
... A45: 259 | B45: SB6 | C45: NA | D45: 259 | E45: Std 69 | F45: F220930s259.CHR | G45: 44835 | H45: 0.29041667 | I45: CH4 | J45: 1.386 | K45: 9883.4384 | L45: 42748.37 | M45: ppm | N45: CO2 | O45: 1.93 | P45: 11760.714 | Q45: 43255.058 | R45: ppm | S45: E220930s259.CHR | T45: 44835 | U45: 0.29041667 | V45: O2 | W45: 1.156 | X45: 1177.0642 | Y45: 9906.6339 | Z45: N2O | AA45: 2.233 | AB45: 4851.2575 | AC45: 19.686 | AD45: ppm | AE45: 49990 | AF45: 60340 | AG45: 20 | AH45: 0

Sheet Run 1 Curve Parameters
A1: Run | B1: Curve | C1: Analyte | D1: Slope | E1: Intercept | F1: RSQ
A2: 1 | B2: 1 | C2: CH4 | D2: =SLOPE('Run 1 Curves 1'!AF37:AF55,'Run 1 Curves 1'!K37:K55) -> 6.0888724 | E2: =INTERCEPT('Run 1 Curves 1'!AF37:AF55,'Run 1 Curves 1'!K37:K55) -> -108.77106 | F2: =RSQ('Run 1 Curves 1'!AF37:AF55,'Run 1 Curves 1'!K37:K55) -> 0.99878912
A3: 1 | B3: 1 | C3: CO2 | D3: =SLOPE('Run 1 Curves 1'!AE37:AE55,'Run 1 Curves 1'!P37:P55) -> 4.172924 | E3: =INTERCEPT('Run 1 Curves 1'!AE37:AE55,'Run 1 Curves 1'!P37:P55) -> -211.72568 | F3: =RSQ('Run 1 Curves 1'!AE37:AE55,'Run 1 Curves 1'!P37:P55) -> 0.99945152
A4: 1 | B4: 1 | C4: O2 | D4: =SLOPE('Run 1 Curves 1'!AH37:AH55,'Run 1 Curves 1'!X37:X55) -> 78.198437 | E4: =INTERCEPT('Run 1 Curves 1'!AH37:AH55,'Run 1 Curves 1'!X37:X55) -> -91237.37 | F4: =RSQ('Run 1 Curves 1'!AH37:AH55,'Run 1 Curves 1'!X37:X55) -> 0.97742642
A5: 1 | B5: 1 | C5: N2O | D5: =SLOPE('Run 1 Curves 1'!AG37:AG55,'Run 1 Curves 1'!AB37:AB55) -> 0.0041355073 | E5: =INTERCEPT('Run 1 Curves 1'!AG37:AG55,'Run 1 Curves 1'!AB37:AB55) -> -0.051146456 | F5: =RSQ('Run 1 Curves 1'!AG37:AG55,'Run 1 Curves 1'!AB37:AB55) -> 0.99979635
A6: 1 | B6: 2 | C6: CH4 | D6: =SLOPE('Run 1 Curves 2'!AF37:AF55,'Run 1 Curves 2'!K37:K55) -> 6.108056 | E6: =INTERCEPT('Run 1 Curves 2'!AF37:AF55,'Run 1 Curves 2'!K37:K55) -> -243.94784 | F6: =RSQ('Run 1 Curves 2'!AF37:AF55,'Run 1 Curves 2'!K37:K55) -> 0.99880845
A7: 1 | B7: 2 | C7: CO2 | D7: =SLOPE('Run 1 Curves 2'!AE37:AE55,'Run 1 Curves 2'!P37:P55) -> 4.2630469 | E7: =INTERCEPT('Run 1 Curves 2'!AE37:AE55,'Run 1 Curves 2'!P37:P55) -> -391.44779 | F7: =RSQ('Run 1 Curves 2'!AE37:AE55,'Run 1 Curves 2'!P37:P55) -> 0.99932485
A8: 1 | B8: 2 | C8: O2 | D8: =SLOPE('Run 1 Curves 2'!AH37:AH55,'Run 1 Curves 2'!X37:X55) -> 86.644804 | E8: =INTERCEPT('Run 1 Curves 2'!AH37:AH55,'Run 1 Curves 2'!X37:X55) -> -113754.61 | F8: =RSQ('Run 1 Curves 2'!AH37:AH55,'Run 1 Curves 2'!X37:X55) -> 0.97779529
A9: 1 | B9: 2 | C9: N2O | D9: =SLOPE('Run 1 Curves 2'!AG37:AG55,'Run 1 Curves 2'!AB37:AB55) -> 0.0041281518 | E9: =INTERCEPT('Run 1 Curves 2'!AG37:AG55,'Run 1 Curves 2'!AB37:AB55) -> -0.10483573 | F9: =INTERCEPT('Run 1 Curves 2'!AG37:AG55,'Run 1 Curves 2'!AB37:AB55) -> -0.10483573

Sheet Data Run 1
A1: Autosampler Position | B1: Species ID | C1: Tree ID | D1: Lab No | E1: Lab ID | F1: FID File | G1: FID Date | H1: FID Time | I1: FID Channel CH4 | J1: Certified Value CO2 | K1: CH4 Area | L1: CH4 ppm | M1: CH4 Unit | N1: FID Channel CO2 | O1: Certified Value CO2 | P1: CO2 Area | Q1: CO2 ppm | R1: CO2 Unit | S1: ECD File | T1: ECD Date | U1: ECD Time | V1: ECD Channel O2 | W1: Certified Value O2 | X1: O2 Area | Y1: O2 ppm | Z1: ECD Channel N2O | AA1: Certified Value N2O | AB1: N2O Area | AC1: N2O ppm | AD1: N2O Unit | AE1: [CO2] (ppm) Curve 1 | AF1: [CH4] (ppm) Curve 1 | AG1: [N2O] (ppm) Curve 1 | AH1: [O2] (ppm) Curve 1 | AI1: [CO2] (ppm) Curve 2 | AJ1: [CH4] (ppm) Curve 2 | AK1: [N2O] (ppm) Curve 2 | AL1: [O2] (ppm) Curve 2
A2: 1 | B2: Lab Air Blank | C2: NA | D2: 1 | E2: Std1 | F2: F220930s01.CHR | G2: 44834 | H2: 0.32184028 | I2: CH4 | J2: 1.4 | K2: 0.2784 | L2: 1.5221 | M2: ppm | N2: CO2 | O2: 1.913 | P2: 95.474 | Q2: 143.2872 | R2: ppm | S2: E220930s01.CHR | T2: 44834 | U2: 0.32184028 | V2: O2 | W2: 1.163 | X2: 3236.0892 | Y2: 137445.32 | Z2: N2O | AA2: 2.213 | AB2: 51.8202 | AC2: 0.0136 | AD2: ppm | AE2: =P2*'Run 1 Curve Parameters'!$D$3+'Run 1 Curve Parameters'!$E$3 -> 186.68006 | AF2: =K2*'Run 1 Curve Parameters'!$D$2+'Run 1 Curve Parameters'!$E$2 -> -107.07591
A3: 2 | B3: Lab Air Blank | C3: NA | D3: 2 | E3: Std2 | F3: F220930s02.CHR | G3: 44834 | H3: 0.32559028 | I3: CH4 | J3: 1.406 | K3: 0.2904 | L3: 1.574 | M3: ppm | N3: CO2 | O3: 1.92 | P3: 89.7547 | Q3: 122.1501 | R3: ppm | S3: E220930s02.CHR | T3: 44834 | U3: 0.32559028 | V3: O2 | W3: 1.166 | X3: 3113.7458 | Y3: 125334.54 | Z3: N2O | AA3: 2.216 | AB3: 49.3968 | AC3: 0.0037 | AD3: ppm | AE3: =P3*'Run 1 Curve Parameters'!$D$3+'Run 1 Curve Parameters'!$E$3 -> 162.81386 | AF3: =K3*'Run 1 Curve Parameters'!$D$2+'Run 1 Curve Parameters'!$E$2 -> -107.00285
A4: 3 | B4: Lab Air Blank | C4: NA | D4: 3 | E4: Std3 | F4: F220930s03.CHR | G4: 44834 | H4: 0.32934028 | I4: CH4 | J4: 1.4 | K4: 0.3183 | L4: 1.6946 | M4: ppm | N4: CO2 | O4: 1.913 | P4: 102.7178 | Q4: 170.0584 | R4: ppm | S4: E220930s03.CHR | T4: 44834 | U4: 0.32934028 | V4: O2 | W4: 1.163 | X4: 3259.7308 | Y4: 139916.85 | Z4: N2O | AA4: 2.21 | AB4: 59.891 | AC4: 0.0467 | AD4: ppm | AE4: =P4*'Run 1 Curve Parameters'!$D$3+'Run 1 Curve Parameters'!$E$3 -> 216.90789 | AF4: =K4*'Run 1 Curve Parameters'!$D$2+'Run 1 Curve Parameters'!$E$2 -> -106.83297
A5: 4 | B5: Lab Air Blank | C5: NA | D5: 4 | E5: Std4 | F5: F220930s04.CHR | G5: 44834 | H5: 0.33309028 | I5: CH4 | J5: 1.403 | K5: 0.3652 | L5: 1.8975 | M5: ppm | N5: CO2 | O5: 1.916 | P5: 109.1048 | Q5: 193.6631 | R5: ppm | S5: E220930s04.CHR | T5: 44834 | U5: 0.33309028 | V5: O2 | W5: 1.163 | X5: 3417.0822 | Y5: 159076.31 | Z5: N2O | AA5: 2.213 | AB5: 62.9926 | AC5: 0.0594 | AD5: ppm | AE5: =P5*'Run 1 Curve Parameters'!$D$3+'Run 1 Curve Parameters'!$E$3 -> 243.56035 | AF5: =K5*'Run 1 Curve Parameters'!$D$2+'Run 1 Curve Parameters'!$E$2 -> -106.5474
A6: 5 | B6: Lab Air Blank | C6: NA | D6: 5 | E6: Std5 | F6: F220930s05.CHR | G6: 44834 | H6: 0.33685185 | I6: CH4 | J6: 1.403 | K6: 0.2958 | L6: 1.5973 | M6: ppm | N6: CO2 | O6: 1.913 | P6: 90.868 | Q6: 126.2646 | R6: ppm | S6: E220930s05.CHR | T6: 44834 | U6: 0.33685185 | V6: O2 | W6: 1.16 | X6: 3152.4221 | Y6: 129013.1 | Z6: N2O | AA6: 2.21 | AB6: 55.7088 | AC6: 0.0296 | AD6: ppm | AE6: =P6*'Run 1 Curve Parameters'!$D$3+'Run 1 Curve Parameters'!$E$3 -> 167.45957 | AF6: =K6*'Run 1 Curve Parameters'!$D$2+'Run 1 Curve Parameters'!$E$2 -> -106.96997
A7: 6 | B7: Lab Air Blank | C7: NA | D7: 6 | E7: Std6 | F7: F220930s06.CHR | G7: 44834 | H7: 0.34061343 | I7: CH4 | J7: 1.41 | K7: 0.307 | L7: 1.6458 | M7: ppm | N7: CO2 | O7: 1.923 | P7: 88.9572 | Q7: 119.2027 | R7: ppm | S7: E220930s06.CHR | T7: 44834 | U7: 0.34061343 | V7: O2 | W7: 1.166 | X7: 3163.6668 | Y7: 130108.88 | Z7: N2O | AA7: 2.223 | AB7: 53.4684 | AC7: 0.0204 | AD7: ppm | AE7: =P7*'Run 1 Curve Parameters'!$D$3+'Run 1 Curve Parameters'!$E$3 -> 159.48595 | AF7: =K7*'Run 1 Curve Parameters'!$D$2+'Run 1 Curve Parameters'!$E$2 -> -106.90177
A8: 7 | B8: Lab Air Blank | C8: NA | D8: 7 | E8: Std7 | F8: F220930s07.CHR | G8: 44834 | H8: 0.34436343 | I8: CH4 | J8: 1.413 | K8: 0.3333 | L8: 1.7595 | M8: ppm | N8: CO2 | O8: 1.926 | P8: 98.7931 | Q8: 155.5537 | R8: ppm | S8: E220930s07.CHR | T8: 44834 | U8: 0.34436343 | V8: O2 | W8: 1.17 | X8: 3300.4507 | Y8: 144501.4 | Z8: N2O | AA8: 2.226 | AB8: 56.1868 | AC8: 0.0315 | AD8: ppm | AE8: =P8*'Run 1 Curve Parameters'!$D$3+'Run 1 Curve Parameters'!$E$3 -> 200.53041 | AF8: =K8*'Run 1 Curve Parameters'!$D$2+'Run 1 Curve Parameters'!$E$2 -> -106.74163
A9: 8 | B9: Lab Air Blank | C9: NA | D9: 8 | E9: Std8 | F9: F220930s08.CHR | G9: 44834 | H9: 0.34811343 | I9: CH4 | J9: 1.4 | K9: 0.3154 | L9: 1.6821 | M9: ppm | N9: CO2 | O9: 1.913 | P9: 94.3666 | Q9: 139.1945 | R9: ppm | S9: E220930s08.CHR | T9: 44834 | U9: 0.34811343 | V9: O2 | W9: 1.16 | X9: 3154.477 | Y9: 129213.35 | Z9: N2O | AA9: 2.21 | AB9: 53.4439 | AC9: 0.0203 | AD9: ppm | AE9: =P9*'Run 1 Curve Parameters'!$D$3+'Run 1 Curve Parameters'!$E$3 -> 182.05896 | AF9: =K9*'Run 1 Curve Parameters'!$D$2+'Run 1 Curve Parameters'!$E$2 -> -106.85063
A10: 9 | B10: Lab Air Blank | C10: NA | D10: 9 | E10: Std9 | F10: F220930s09.CHR | G10: 44834 | H10: 0.35186343 | I10: CH4 | J10: 1.41 | K10: 0.2837 | L10: 1.545 | M10: ppm | N10: CO2 | O10: 1.926 | P10: 84.5659 | Q10: 102.9736 | R10: ppm | S10: E220930s09.CHR | T10: 44834 | U10: 0.35186343 | V10: O2 | W10: 1.166 | X10: 3065.4079 | Y10: 120923.37 | Z10: N2O | AA10: 2.226 | AB10: 50.3889 | AC10: 0.0078 | AD10: ppm | AE10: =P10*'Run 1 Curve Parameters'!$D$3+'Run 1 Curve Parameters'!$E$3 -> 141.16139 | AF10: =K10*'Run 1 Curve Parameters'!$D$2+'Run 1 Curve Parameters'!$E$2 -> -107.04364
A11: 10 | B11: Lab Air Blank | C11: NA | D11: 10 | E11: Std10 | F11: F220930s10.CHR | G11: 44834 | H11: 0.35561343 | I11: CH4 | J11: 1.406 | K11: 0.3539 | L11: 1.8486 | M11: ppm | N11: CO2 | O11: 1.923 | P11: 109.2335 | Q11: 194.1388 | R11: ppm | S11: E220930s10.CHR | T11: 44834 | U11: 0.35561343 | V11: O2 | W11: 1.17 | X11: 3316.991 | Y11: 146366.28 | Z11: N2O | AA11: 2.22 | AB11: 59.3886 | AC11: 0.0447 | AD11: ppm | AE11: =P11*'Run 1 Curve Parameters'!$D$3+'Run 1 Curve Parameters'!$E$3 -> 244.09741 | AF11: =K11*'Run 1 Curve Parameters'!$D$2+'Run 1 Curve Parameters'!$E$2 -> -106.6162
A12: 11 | B12: N2 | C12: NA | D12: 11 | E12: Std11 | F12: F220930s11.CHR | G12: 44834 | H12: 0.359375 | I12: CH4 | J12: 0 | K12: 0 | L12: 0 | M12: ppm | N12: CO2 | O12: 1.923 | P12: 42.255 | Q12: 0 | R12: ppm | S12: E220930s11.CHR | T12: 44834 | U12: 0.359375 | V12: O2 | W12: 1.166 | X12: 1197.8328 | Y12: 10817.772 | Z12: N2O | AA12: 2.22 | AB12: 18.776 | AC12: 0 | AD12: ppm | AE12: =P12*'Run 1 Curve Parameters'!$D$3+'Run 1 Curve Parameters'!$E$3 -> -35.398779 | AF12: =K12*'Run 1 Curve Parameters'!$D$2+'Run 1 Curve Parameters'!$E$2 -> -108.77106
A13: 12 | B13: Lab Air Blank | C13: NA | D13: 12 | E13: Std12 | F13: F220930s12.CHR | G13: 44834 | H13: 0.36313657 | I13: CH4 | J13: 1.406 | K13: 0.2922 | L13: 1.5817 | M13: ppm | N13: CO2 | O13: 1.92 | P13: 82.3047 | Q13: 94.6168 | R13: ppm | S13: E220930s12.CHR | T13: 44834 | U13: 0.36313657 | V13: O2 | W13: 1.166 | X13: 2901.2608 | Y13: 107152.77 | Z13: N2O | AA13: 2.216 | AB13: 48.3396 | AC13: 0 | AD13: ppm | AE13: =P13*'Run 1 Curve Parameters'!$D$3+'Run 1 Curve Parameters'!$E$3 -> 131.72557 | AF13: =K13*'Run 1 Curve Parameters'!$D$2+'Run 1 Curve Parameters'!$E$2 -> -106.99189
... A55: 54 | B55: Lab Air Blank | C55: NA | D55: 54 | E55: Std54 | F55: F220930s54.CHR | G55: 44834 | H55: 0.52103009 | I55: CH4 | J55: 1.41 | K55: 0.3578 | L55: 1.8655 | M55: ppm | N55: CO2 | O55: 1.946 | P55: 99.1488 | Q55: 156.8683 | R55: ppm | S55: E220930s54.CHR | T55: 44834 | U55: 0.52103009 | V55: O2 | W55: 1.166 | X55: 3073.4656 | Y55: 121658.69 | Z55: N2O | AA55: 2.256 | AB55: 62.1319 | AC55: 0.0559 | AD55: ppm | AE55: =P55*'Run 1 Curve Parameters'!$D$3+'Run 1 Curve Parameters'!$E$3 -> 202.01472 | AF55: =K55*'Run 1 Curve Parameters'!$D$2+'Run 1 Curve Parameters'!$E$2 -> -106.59246
A56: 55 | B56: ACRU | C56: RM1 | D56: 55 | E56: =D56&"g" -> 55g | F56: F220930s55.CHR | G56: 44834 | H56: 0.52478009 | I56: CH4 | J56: 1.41 | K56: 6.239 | L56: 27.303 | M56: ppm | N56: CO2 | O56: 1.94 | P56: 17693.369 | Q56: 65180.644 | R56: ppm | S56: E220930s55.CHR | T56: 44834 | U56: 0.52478009 | V56: O2 | W56: 1.16 | X56: 2745.5214 | Y56: 95433.521 | Z56: N2O | AA56: 2.25 | AB56: 350.1718 | AC56: 1.2365 | AD56: ppm | AE56: =P56*'Run 1 Curve Parameters'!$D$3+'Run 1 Curve Parameters'!$E$3 -> 73621.357 | AF56: =K56*'Run 1 Curve Parameters'!$D$2+'Run 1 Curve Parameters'!$E$2 -> -70.78258
A57: 56 | B57: BLANK | C57: BLANK | D57: 56 | E57: BLANK | F57: F220930s56.CHR | G57: 44834 | H57: 0.52853009 | I57: CH4 | J57: 0 | K57: 0 | L57: 0 | M57: ppm | N57: CO2 | O57: 1.956 | P57: 154.6102 | Q57: 361.8396 | R57: ppm | S57: E220930s56.CHR | T57: 44834 | U57: 0.52853009 | V57: O2 | W57: 1.166 | X57: 3198.6341 | Y57: 133529.72 | Z57: N2O | AA57: 2.263 | AB57: 66.5488 | AC57: 0.074 | AD57: ppm | AE57: =P57*'Run 1 Curve Parameters'!$D$3+'Run 1 Curve Parameters'!$E$3 -> 433.45093 | AF57: =K57*'Run 1 Curve Parameters'!$D$2+'Run 1 Curve Parameters'!$E$2 -> -108.77106
A58: 57 | B58: ACRU | C58: RM10 | D58: 57 | E58: =D58&"g" -> 57g | F58: F220930s57.CHR | G58: 44834 | H58: 0.53228009 | I58: CH4 | J58: 1.42 | K58: 14.824 | L58: 64.435 | M58: ppm | N58: CO2 | O58: 1.966 | P58: 7544.7502 | Q58: 27673.923 | R58: ppm | S58: E220930s57.CHR | T58: 44834 | U58: 0.53228009 | V58: O2 | W58: 1.17 | X58: 3445.2342 | Y58: 163133.28 | Z58: N2O | AA58: 2.26 | AB58: 238.073 | AC58: 0.7771 | AD58: ppm | AE58: =P58*'Run 1 Curve Parameters'!$D$3+'Run 1 Curve Parameters'!$E$3 -> 31271.943 | AF58: =K58*'Run 1 Curve Parameters'!$D$2+'Run 1 Curve Parameters'!$E$2 -> -18.509611
A59: 58 | B59: BLANK | C59: BLANK | D59: 58 | E59: BLANK | F59: F220930s58.CHR | G59: 44834 | H59: 0.53603009 | I59: CH4 | J59: 1.4 | K59: 0.2757 | L59: 1.5104 | M59: ppm | N59: CO2 | O59: 1.94 | P59: 146.9986 | Q59: 333.709 | R59: ppm | S59: E220930s58.CHR | T59: 44834 | U59: 0.53603009 | V59: O2 | W59: 1.16 | X59: 3168.6772 | Y59: 130597.14 | Z59: N2O | AA59: 2.246 | AB59: 66.7244 | AC59: 0.0747 | AD59: ppm | AE59: =P59*'Run 1 Curve Parameters'!$D$3+'Run 1 Curve Parameters'!$E$3 -> 401.6883 | AF59: =K59*'Run 1 Curve Parameters'!$D$2+'Run 1 Curve Parameters'!$E$2 -> -107.09235
A60: 59 | B60: ACRU | C60: RM14 | D60: 59 | E60: =D60&"g" -> 59g | F60: F220930s59.CHR | G60: 44834 | H60: 0.53978009 | I60: CH4 | J60: 1.406 | K60: 0.5796 | L60: 2.8248 | M60: ppm | N60: CO2 | O60: 1.94 | P60: 812.0508 | Q60: 2791.5733 | R60: ppm | S60: E220930s59.CHR | T60: 44834 | U60: 0.53978009 | V60: O2 | W60: 1.16 | X60: 3542.5475 | Y60: 177484.93 | Z60: N2O | AA60: 2.243 | AB60: 112.7424 | AC60: 0.2633 | AD60: ppm | AE60: =P60*'Run 1 Curve Parameters'!$D$3+'Run 1 Curve Parameters'!$E$3 -> 3176.9006 | AF60: =K60*'Run 1 Curve Parameters'!$D$2+'Run 1 Curve Parameters'!$E$2 -> -105.24194
A61: 60 | B61: BLANK | C61: BLANK | D61: 60 | E61: BLANK | F61: F220930s60.CHR | G61: 44834 | H61: 0.54353009 | I61: CH4 | J61: 1.416 | K61: 0.2706 | L61: 1.4883 | M61: ppm | N61: CO2 | O61: 1.95 | P61: 85.9286 | Q61: 108.0098 | R61: ppm | S61: E220930s60.CHR | T61: 44834 | U61: 0.54353009 | V61: O2 | W61: 1.17 | X61: 3020.281 | Y61: 116996.09 | Z61: N2O | AA61: 2.26 | AB61: 52.3992 | AC61: 0.016 | AD61: ppm | AE61: =P61*'Run 1 Curve Parameters'!$D$3+'Run 1 Curve Parameters'!$E$3 -> 146.84783 | AF61: =K61*'Run 1 Curve Parameters'!$D$2+'Run 1 Curve Parameters'!$E$2 -> -107.12341
A62: 61 | B62: ACRU | C62: RM2 | D62: 61 | E62: =D62&"g" -> 61g | F62: F220930s61.CHR | G62: 44834 | H62: 0.54726852 | I62: CH4 | J62: 1.406 | K62: 0.6522 | L62: 3.1388 | M62: ppm | N62: CO2 | O62: 1.94 | P62: 418.3445 | Q62: 1336.5347 | R62: ppm | S62: E220930s61.CHR | T62: 44834 | U62: 0.54726852 | V62: O2 | W62: 1.16 | X62: 3567.1041 | Y62: 181106.5 | Z62: N2O | AA62: 2.243 | AB62: 96.932 | AC62: 0.1985 | AD62: ppm | AE62: =P62*'Run 1 Curve Parameters'!$D$3+'Run 1 Curve Parameters'!$E$3 -> 1533.9941 | AF62: =K62*'Run 1 Curve Parameters'!$D$2+'Run 1 Curve Parameters'!$E$2 -> -104.79989
A63: 62 | B63: BLANK | C63: BLANK | D63: 62 | E63: BLANK | F63: F220930s62.CHR | G63: 44834 | H63: 0.55101852 | I63: CH4 | J63: 1.403 | K63: 0.3002 | L63: 1.6163 | M63: ppm | N63: CO2 | O63: 1.936 | P63: 93.5298 | Q63: 136.1019 | R63: ppm | S63: E220930s62.CHR | T63: 44834 | U63: 0.55101852 | V63: O2 | W63: 1.16 | X63: 2985.6592 | Y63: 114025.35 | Z63: N2O | AA63: 2.243 | AB63: 60.1067 | AC63: 0.0476 | AD63: ppm | AE63: =P63*'Run 1 Curve Parameters'!$D$3+'Run 1 Curve Parameters'!$E$3 -> 178.56706 | AF63: =K63*'Run 1 Curve Parameters'!$D$2+'Run 1 Curve Parameters'!$E$2 -> -106.94318
A64: 63 | B64: ACRU | C64: RM3 | D64: 63 | E64: =D64&"g" -> 63g | F64: F220930s63.CHR | G64: 44834 | H64: 0.55475694 | I64: CH4 | J64: 1.406 | K64: 5.5582 | L64: 24.3584 | M64: ppm | N64: CO2 | O64: 1.943 | P64: 12837.626 | Q64: 47235.052 | R64: ppm | S64: E220930s63.CHR | T64: 44834 | U64: 0.55475694 | V64: O2 | W64: 1.156 | X64: 3030.5881 | Y64: 117880.49 | Z64: N2O | AA64: 2.24 | AB64: 290.5474 | AC64: 0.9921 | AD64: ppm | AE64: =P64*'Run 1 Curve Parameters'!$D$3+'Run 1 Curve Parameters'!$E$3 -> 53358.713 | AF64: =K64*'Run 1 Curve Parameters'!$D$2+'Run 1 Curve Parameters'!$E$2 -> -74.927885
A65: 64 | B65: BLANK | C65: BLANK | D65: 64 | E65: BLANK | F65: F220930s64.CHR | G65: 44834 | H65: 0.55850694 | I65: CH4 | J65: 0 | K65: 0 | L65: 0 | M65: ppm | N65: CO2 | O65: 1.94 | P65: 89.08 | Q65: 119.6566 | R65: ppm | S65: E220930s64.CHR | T65: 44834 | U65: 0.55850694 | V65: O2 | W65: 1.16 | X65: 2872.0868 | Y65: 104890.72 | Z65: N2O | AA65: 2.25 | AB65: 51.8336 | AC65: 0.0137 | AD65: ppm | AE65: =P65*'Run 1 Curve Parameters'!$D$3+'Run 1 Curve Parameters'!$E$3 -> 159.99839 | AF65: =K65*'Run 1 Curve Parameters'!$D$2+'Run 1 Curve Parameters'!$E$2 -> -108.77106
A66: 65 | B66: ACRU | C66: RM301A | D66: 65 | E66: =D66&"g" -> 65g | F66: F220930s65.CHR | G66: 44834 | H66: 0.56225694 | I66: CH4 | J66: 1.42 | K66: 69.3912 | L66: 300.4502 | M66: ppm | N66: CO2 | O66: 1.966 | P66: 4780.4642 | Q66: 17457.823 | R66: ppm | S66: E220930s65.CHR | T66: 44834 | U66: 0.56225694 | V66: O2 | W66: 1.166 | X66: 3423.3818 | Y66: 159918.85 | Z66: N2O | AA66: 2.26 | AB66: 195.1246 | AC66: 0.601 | AD66: ppm | AE66: =P66*'Run 1 Curve Parameters'!$D$3+'Run 1 Curve Parameters'!$E$3 -> 19736.788 | AF66: =K66*'Run 1 Curve Parameters'!$D$2+'Run 1 Curve Parameters'!$E$2 -> 313.74311
A67: 66 | B67: BLANK | C67: BLANK | D67: 66 | E67: BLANK | F67: F220930s66.CHR | G67: 44834 | H67: 0.56599537 | I67: CH4 | J67: 1.403 | K67: 0.3121 | L67: 1.6678 | M67: ppm | N67: CO2 | O67: 1.943 | P67: 100.2808 | Q67: 161.0519 | R67: ppm | S67: E220930s66.CHR | T67: 44834 | U67: 0.56599537 | V67: O2 | W67: 1.16 | X67: 2928.1402 | Y67: 109329.14 | Z67: N2O | AA67: 2.256 | AB67: 57.9934 | AC67: 0.0389 | AD67: ppm | AE67: =P67*'Run 1 Curve Parameters'!$D$3+'Run 1 Curve Parameters'!$E$3 -> 206.73847 | AF67: =K67*'Run 1 Curve Parameters'!$D$2+'Run 1 Curve Parameters'!$E$2 -> -106.87072
